Workbook

Sheet Validator Notes
A4: Site | B4: EQ - Utah Technical Center
A5: Month/Year | B5: Month 2025
A6: Validator | B6: Aengstrom
A8: Validation Prep: | E8: Notes:
B9: Verify all Daily-ZIP folders are downloaded into U:\PLAN\AMC\GC-Agilent+Markes\Data\ORIGINAL\{YYYY}\{YYYYMM}
B10: Verify Operator Reprocessed zip folders are downloaded into U:\PLAN\AMC\GC-Agilent+Markes\Data\ORIGINAL\{YYYY}\{YYYYMM}
B11: Verify all data has been extracted to C:\Users\{Username}\Documents\AutoGC Data\{SiteID}\{YYYY}\{YYYYMM}
B12: Ensure dates, times, and site names/numbers in files match up and are continuous. document any missing files on the Validation Notes.
B13: Verify all Original TX1 files loaded into MAX
B14: Check CVS, Blanks, and LCS Reports and notate failures
B15: Download Crosstab into MDVR folder pre changes
A17: Review Oplog:
B18: View and Print the Operator Log Book (Desktop), Op Log backup (D:\EZ\HW-meth), and Operator Checklist (Desktop) from the HW-GC computer with 72 hours on either side of the month. Review and highlight major events in the operator log book such as optimizations, cylinder changes, major events (calibrations), major malfunctions (power failures, trap, oven door failures), etc. Highlight hours for review during or around major events as necessary per operator log book.
B19: Stock Cylinder Changes - Verify in MAX
B20: Correct PE Audit Samples
B21: Correct MDL Samples - Create Spreadsheet
B22: Annual PM
B23: 3pt Curve - Calculated RPD
A25: Review Quicklooks:
B26: Dates (1-31) Hours (A-X)
B27: Invalidate missing hours
B28: Over-ranges - If valid: remove flag, recal & store, update excel
B29: Invalidate data collection errors
B30: Pick hours to view (1st/last month, surrounding invalidations)
B31: Highlight at least 3 hours to review daily on each column’s hourly grid page. Ideally one hour will be reviewed for each of the following time span; Morning Commute (06-09), Afternoon (11-15); Night (0-4, or16-23). Try not to exceede 6hr.
A33: Review Chromatography: | E33: CVS Std | F33: BR | G33: LCS Std | H33: DF | I33: RTS Std | J33: BR | K33: 1) RSD (Plot) = | L33: =IF(G38="","",E38&" + "&G38) | M33: =IF(G38="","",(ABS((E38-G38))/G38))
B34: All QC samples have been viewed | L34: =IF(G38="","",G38)
B35: All highlighted hours have been viewed | K35: 1) RSD (BP) = | L35: =IF(H38="","",F38&" + "&H38) | M35: =IF(H38="","",(ABS((F38-H38)/H38)))
B36: If reprocessed, viewed reprocessed QC/Ambient | E36: Starting RF | G36: Ending RF | I36: ReCal Date(s) | L36: =IF(H38="","",H38)
B37: View hours before & after reprocessed data | E37: PLOT | F37: BP1 | G37: PLOT | H37: BP1 | I37: ReCal Date(s) | K37: 2) RSD (Plot) = | L37: =IF(G39="","",E39&" + "&G39) | M37: =IF(G39="","",(ABS((E39-G39))/G39))
B38: View hours before & after invalidations | L38: =IF(G39="","",G39)
B39: Invalidate TMNHC/TC if invalidating 8+ compounds | K39: 2) RSD (BP) = | L39: =IF(H39="","",F39&" + "&H39) | M39: =IF(H39="","",(ABS((F39-H39)/H39)))
B40: >336 hour, 14-days, of data loss; update Reprocess Plan | E40: EH = | L40: =IF(H39="","",H39)
B41: Send necessary emails and save copy in the MDVR folder for general issues, 336-hr data losses, and ambient over-ranges.
A44: Validator Notes
A46: Site | B46: =B4 -> EQ - Utah Technical Center
A47: Month/Year | B47: =B5 -> Month 2025
A48: Validator | B48: =B6 -> Aengstrom
A50: Review Reprocess Plan: | E50: Notes:
B51: Number of tx1s matches Reprocess Data
...

Sheet QC Review
A1: QC (CVS, CVS Precision, LCS, RTS, BLANK, Audit) Review
A3: Site | B3: ='Validator Notes'!B4 -> EQ - Utah Technical Center | D3: Validator | E3: ='Validator Notes'!B6 -> Aengstrom
A4: Month/Year | B4: ='Validator Notes'!B5 -> Month 2025
A6: QC Type | B6: Date/Time | D6: Filename | E6: Plot Column Notes | F6: BP Notes | G6: Actions
A7: RTS
A15: LCS
A22: CVS
A62: CVS Precision
A72: Audit
A73: Blank
A111: Exp. Or Test Sample
AD158: Qulaifier Flag, MD, was applied to all paramaters and hours that measured below the MDL; Qulaifier Flag, ND, was applied to all paramaters and hours that where not detected; Qulaifier Flag, EH, was applied to Isoprene, 2-METHYL-1-PENTENE, 1-Hexene, and n-Dodecane - due to questions about the accuracy of the measurments at the end of the column; Qualif Flag, QX, was applied to ACETYLENE for whole month due to low CVS recovery; Qualif Flag, QX, was applied to BETA-PINENE from 5-1 to 5-16 due to high blank value;

Sheet Reprocessed Data
A3: Site | B3: ='Validator Notes'!B4 -> EQ - Utah Technical Center
A4: Month/Year | B4: ='Validator Notes'!B5 -> Month 2025
A5: Validator | B5: ='Validator Notes'!B6 -> Aengstrom
C7: Batch | E7: single file rpo | F7: Data Range | L7: Date
A8: Column | B8: Corrections Made | C8: Sequence | D8: method | E8: data file | F8: Date | G8: Hour | H8: - | I8: Date | J8: Hour | L8: RPO
C31: Batch | E31: single file rpo | F31: Data Range | L31: Date
A32: Column | B32: Corrections Made | C32: Sequence | D32: method | E32: data file | F32: Date | G32: Hour | H32: - | I32: Date | J32: Hour | L32: RPO
C60: Batch | E60: single file rpo | F60: Data Range | L60: Date
A61: Column | B61: Corrections Made | C61: Sequence | D61: method | E61: data file | F61: Date | G61: Hour | H61: - | I61: Date | J61: Hour | L61: RPO
AC89: Qulaifier Flag, MD, was applied to all paramaters and hours that measured below the MDL; Qulaifier Flag, ND, was applied to all paramaters and hours that where not detected; Qulaifier Flag, EH, was applied to Isoprene, 2-METHYL-1-PENTENE, 1-Hexene, and n-Dodecane - due to questions about the accuracy of the measurments at the end of the column; Qualif Flag, QX, was applied to ACETYLENE for whole month due to low CVS recovery; Qualif Flag, QX, was applied to BETA-PINENE from 5-1 to 5-16 due to high blank value;

Sheet Reprocess Plan
C2: Reprocess Plan | N2: Site: | P2: ='Validator Notes'!B4 -> EQ - Utah Technical Center | V2: Month/Year: | Z2: ='Validator Notes'!B5 -> Month 2025 | AZ2: Pg. | BA2: 1
E4: 1 | AD4: 2 | BD4: CVS
E5: 0 | F5: 1 | G5: 2 | H5: 3 | I5: 4 | J5: 5 | K5: 6 | L5: 7 | M5: 8 | N5: 9 | O5: 10 | P5: 11 | Q5: 12 | R5: 13 | S5: 14 | T5: 15 | U5: 16 | V5: 17 | W5: 18 | X5: 19 | Y5: 20 | Z5: 21 | AA5: 22 | AB5: 23 | AD5: 0 | AE5: 1 | AF5: 2 | AG5: 3 | AH5: 4 | AI5: 5 | AJ5: 6 | AK5: 7 | AL5: 8 | AM5: 9 | AN5: 10 | AO5: 11 | AP5: 12 | AQ5: 13 | AR5: 14 | AS5: 15 | AT5: 16 | AU5: 17 | AV5: 18 | AW5: 19 | AX5: 20 | AY5: 21 | AZ5: 22 | BA5: 23 | BD5: Blank
E6: A | F6: B | G6: C | H6: D | I6: E | J6: F | K6: G | L6: H | M6: I | N6: J | O6: K | P6: L | Q6: M | R6: N | S6: O | T6: P | U6: Q | V6: R | W6: S | X6: T | Y6: U | Z6: V | AA6: W | AB6: X | AD6: A | AE6: B | AF6: C | AG6: D | AH6: E | AI6: F | AJ6: G | AK6: H | AL6: I | AM6: J | AN6: K | AO6: L | AP6: M | AQ6: N | AR6: O | AS6: P | AT6: Q | AU6: R | AV6: S | AW6: T | AX6: U | AY6: V | AZ6: W | BA6: X | BD6: LCS
C7: Checked PLOT | BD7: RTS
C8: RPO PLOT | BD8: Experimental/ Test
C9: Checked BP | BD9: Missing Data
C10: RPO BP | BD10: Invalidate
C11: Invalid PLOT | BD11: Check this Hour
C12: Invalid BP | BC12: RP | BD12: Reprocessed file
C13: Op Log | BC13: OK | BD13: Hour reviewed and correct
C14: Notes: | BD14: Multipoint
E15: 3 | AD15: 4 | BD15: Detection Limit
E16: 0 | F16: 1 | G16: 2 | H16: 3 | I16: 4 | J16: 5 | K16: 6 | L16: 7 | M16: 8 | N16: 9 | O16: 10 | P16: 11 | Q16: 12 | R16: 13 | S16: 14 | T16: 15 | U16: 16 | V16: 17 | W16: 18 | X16: 19 | Y16: 20 | Z16: 21 | AA16: 22 | AB16: 23 | AD16: 0 | AE16: 1 | AF16: 2 | AG16: 3 | AH16: 4 | AI16: 5 | AJ16: 6 | AK16: 7 | AL16: 8 | AM16: 9 | AN16: 10 | AO16: 11 | AP16: 12 | AQ16: 13 | AR16: 14 | AS16: 15 | AT16: 16 | AU16: 17 | AV16: 18 | AW16: 19 | AX16: 20 | AY16: 21 | AZ16: 22 | BA16: 23 | BC16: SB | BD16: See Below
E17: A | F17: B | G17: C | H17: D | I17: E | J17: F | K17: G | L17: H | M17: I | N17: J | O17: K | P17: L | Q17: M | R17: N | S17: O | T17: P | U17: Q | V17: R | W17: S | X17: T | Y17: U | Z17: V | AA17: W | AB17: X | AD17: A | AE17: B | AF17: C | AG17: D | AH17: E | AI17: F | AJ17: G | AK17: H | AL17: I | AM17: J | AN17: K | AO17: L | AP17: M | AQ17: N | AR17: O | AS17: P | AT17: Q | AU17: R | AV17: S | AW17: T | AX17: U | AY17: V | AZ17: W | BA17: X
C18: Checked PLOT
C19: RPO PLOT
C20: Checked BP
C21: RPO BP
C22: Invalid PLOT
C23: Invalid BP
C24: Op Log
C25: Notes:
E26: 5 | AD26: 6
E27: 0 | F27: 1 | G27: 2 | H27: 3 | I27: 4 | J27: 5 | K27: 6 | L27: 7 | M27: 8 | N27: 9 | O27: 10 | P27: 11 | Q27: 12 | R27: 13 | S27: 14 | T27: 15 | U27: 16 | V27: 17 | W27: 18 | X27: 19 | Y27: 20 | Z27: 21 | AA27: 22 | AB27: 23 | AD27: 0 | AE27: 1 | AF27: 2 | AG27: 3 | AH27: 4 | AI27: 5 | AJ27: 6 | AK27: 7 | AL27: 8 | AM27: 9 | AN27: 10 | AO27: 11 | AP27: 12 | AQ27: 13 | AR27: 14 | AS27: 15 | AT27: 16 | AU27: 17 | AV27: 18 | AW27: 19 | AX27: 20 | AY27: 21 | AZ27: 22 | BA27: 23
E28: A | F28: B | G28: C | H28: D | I28: E | J28: F | K28: G | L28: H | M28: I | N28: J | O28: K | P28: L | Q28: M | R28: N | S28: O | T28: P | U28: Q | V28: R | W28: S | X28: T | Y28: U | Z28: V | AA28: W | AB28: X | AD28: A | AE28: B | AF28: C | AG28: D | AH28: E | AI28: F | AJ28: G | AK28: H | AL28: I | AM28: J | AN28: K | AO28: L | AP28: M | AQ28: N | AR28: O | AS28: P | AT28: Q | AU28: R | AV28: S | AW28: T | AX28: U | AY28: V | AZ28: W | BA28: X
C29: Checked PLOT
C30: RPO PLOT
C31: Checked BP
C32: RPO BP
C33: Invalid PLOT
C34: Invalid BP
C35: Op Log
C36: Notes:
E37: 7 | AD37: 8
E38: 0 | F38: 1 | G38: 2 | H38: 3 | I38: 4 | J38: 5 | K38: 6 | L38: 7 | M38: 8 | N38: 9 | O38: 10 | P38: 11 | Q38: 12 | R38: 13 | S38: 14 | T38: 15 | U38: 16 | V38: 17 | W38: 18 | X38: 19 | Y38: 20 | Z38: 21 | AA38: 22 | AB38: 23 | AD38: 0 | AE38: 1 | AF38: 2 | AG38: 3 | AH38: 4 | AI38: 5 | AJ38: 6 | AK38: 7 | AL38: 8 | AM38: 9 | AN38: 10 | AO38: 11 | AP38: 12 | AQ38: 13 | AR38: 14 | AS38: 15 | AT38: 16 | AU38: 17 | AV38: 18 | AW38: 19 | AX38: 20 | AY38: 21 | AZ38: 22 | BA38: 23
E39: A | F39: B | G39: C | H39: D | I39: E | J39: F | K39: G | L39: H | M39: I | N39: J | O39: K | P39: L | Q39: M | R39: N | S39: O | T39: P | U39: Q | V39: R | W39: S | X39: T | Y39: U | Z39: V | AA39: W | AB39: X | AD39: A | AE39: B | AF39: C | AG39: D | AH39: E | AI39: F | AJ39: G | AK39: H | AL39: I | AM39: J | AN39: K | AO39: L | AP39: M | AQ39: N | AR39: O | AS39: P | AT39: Q | AU39: R | AV39: S | AW39: T | AX39: U | AY39: V | AZ39: W | BA39: X
C40: Checked PLOT
C41: RPO PLOT
C42: Checked BP
...

Sheet QUALIFIERS_NULL 
A1: QUALIFIERS / NULL
A3: Site | B3: ='Validator Notes'!B4 -> EQ - Utah Technical Center
A4: Month/Year | B4: ='Validator Notes'!B5 -> Month 2025
A5: Validator | B5: ='Validator Notes'!B6 -> Aengstrom
A7: Null | R7: Common Null Flags | U7: Null
J8: DATE/TIME RANGE | R8: Code | S8: Description | AD8: DATE/TIME RANGE
A9: Paramater (s) | D9: COMPOUND(S) or WHOLE HOUR(S) - REASON | I9: CODE | J9: Date | K9: Hour | L9: - | M9: Date | N9: Hour | O9: Justification | R9: AF | S9: Scheduled but not Collected (Lost) | U9: Paramater (s) | X9: COMPOUND(S) or WHOLE HOUR(S) - REASON | AC9: CODE | AD9: Date | AE9: Hour | AF9: - | AG9: Date | AH9: Hour | AI9: Justification
K10: 0 | L10: - | N10: 23 | R10: AG | S10: Sample Time Out of Limits | AE10: 0 | AF10: - | AH10: 23
K11: 0 | L11: - | N11: 23 | R11: AH | S11: Sample Flow Rate out of Limits | AE11: 0 | AF11: - | AH11: 23
K12: 0 | L12: - | N12: 23 | R12: AI | S12: Insufficient Data (Invalid Sample Time) | AE12: 0 | AF12: - | AH12: 23
K13: 0 | L13: - | N13: 23 | R13: AM | S13: Misc. Void | AE13: 0 | AF13: - | AH13: 23
K14: 0 | L14: - | N14: 23 | R14: AN | S14: Machine Malfunction | AE14: 0 | AF14: - | AH14: 23
K15: 0 | L15: - | N15: 23 | R15: AQ | S15: Collection Error | AE15: 0 | AF15: - | AH15: 23
K16: 0 | L16: - | N16: 23 | R16: AS | S16: Poor QA results | AE16: 0 | AF16: - | AH16: 23
K17: 0 | L17: - | N17: 23 | R17: AT | S17: Calibration | AE17: 0 | AF17: - | AH17: 23
K18: 0 | L18: - | N18: 23 | R18: AV | S18: Power Failure | AE18: 0 | AF18: - | AH18: 23
K19: 0 | L19: - | N19: 23 | R19: AX | S19: Precision Check | AE19: 0 | AF19: - | AH19: 23
K20: 0 | L20: - | N20: 23 | R20: AY | S20: QC Control Points, Zero/Span | AE20: 0 | AF20: - | AH20: 23
K21: 0 | L21: - | N21: 23 | R21: AZ | S21: QC Audit (Audit Sample) | AE21: 0 | AF21: - | AH21: 23
R22: BA | S22: Maintenances / Routine Repairs
R23: BH | S23: Interference, Co-elution, Misid
R24: BJ | S24: Operator Error
R25: BK | S25: Site Computer, Data Logger Down
R26: DA | S26: Aberrant Data, Corrupt Files, Spikes, Shifts
A27: QUALIFIERS | R27: DL | S27: Detection Limit | U27: QUALIFIERS
J28: DATE/TIME RANGE | R28: TC | S28: Component Check & RTS (RTS) | AD28: DATE/TIME RANGE
A29: Paramater (s) | D29: COMPOUND(S) or WHOLE HOUR(S) - REASON | I29: CODE | J29: Date | K29: Hour | L29: - | M29: Date | N29: Hour | O29: Justification | R29: XX | S29: Experimental Data | U29: Paramater (s) | X29: COMPOUND(S) or WHOLE HOUR(S) - REASON | AC29: CODE | AD29: Date | AE29: Hour | AF29: - | AG29: Date | AH29: Hour | AI29: Justification
K30: 0 | L30: - | N30: 23 | AE30: 0 | AF30: - | AH30: 23
K31: 0 | L31: - | N31: 23 | AE31: 0 | AF31: - | AH31: 23
K32: 0 | L32: - | N32: 23 | AE32: 0 | AF32: - | AH32: 23
K33: 0 | L33: - | N33: 23 | AE33: 0 | AF33: - | AH33: 23
K34: 0 | L34: - | N34: 23 | R34: Common Qualifier Flag | AE34: 0 | AF34: - | AH34: 23
L35: - | R35: Code | S35: Description | AF35: -
L36: - | R36: LJ | S36: ID acceptable; Value is Estimate | AF36: -
L37: - | R37: LL | S37: ID; Value Biased Low | AF37: -
L38: - | R38: LK | S38: ID; Value Biased High | AF38: -
L39: - | R39: QX | S39: Does not Meet QC Criteria | AF39: -
L40: - | R40: EH | S40: Estimated; Exceeds Upper Range | AF40: -
L41: - | R41: ND | S41: No Value Detected; Non Detect | AF41: -
L42: - | R42: MD | S42: Value Less Than MDL (<MDL) | AF42: -
...

Sheet Calculations
A1: Canister | B1: Dilution ratio | C1: propane conc (ppmV) | D1: toluene conc (ppmV) | J1: Canister | K1: Dilution ratio | L1: propane conc (ppmV) | M1: toluene conc (ppmV) | S1: Canister | T1: Dilution ratio | U1: Propane conc (ppbC) | V1: toluene conc (ppbC)
A2: CC524930-0626 | B2: 0.00148 | C2: 0.34 | D2: 0.146 | J2: CC177206-1226 | K2: 0.005 | L2: 0.36 | M2: 0.1526 | S2: CC731198-0126 | T2: 0.00135 | U2: 1040 | V2: 1080
Z3: CVS | AB3: LCS | AD3: RTS
A4: CVS | J4: LCS | S4: RTS | Z4: % Bias | AA4: % Error | AB4: % Bias | AC4: % Error | AD4: % Bias | AE4: % Error
A5: DATE TIME | B5: PROPANE PPBC | C5: Dist | D5: % Recovery Propane | E5: TOLUENE PPBC | F5: Dist | G5: % Recovery Toluene | J5: DATE/TIME | K5: PROPANE (ppbC) | L5: % Recovery Propane | M5: TOLUENE ppbC | N5: % Recovery Toluene | S5: DATE TIME | T5: PROPANE (ppbC) | U5: % Recovery Propane | V5: TOLUENE ppbC | W5: % Recovery Toluene | Y5: Propane | Z5: =B41/B42 -> 1.3988084 | AA5: =B44/B41 -> 0.04589369 | AB5: =K16/K15 -> 23.889482 | AC5: =K10/K16 -> 0 | AD5: =T13/T12 -> 0.90474834 | AE5: =T11/T13 -> 0.013584078
A6: 45901.083 | B6: 2.0144 | C6: =_xlfn.NORM.DIST(B6,$B$41,$B$44,FALSE) -> 2.4883278 | D6: =B6/$B$42*100 -> 133.43932 | E6: 2.0695 | F6: =_xlfn.NORM.DIST(E6,$E$41,$E$44,FALSE) -> 3.314541 | G6: =E6/$E$42*100 -> 136.82102 | J6: 45906.875 | K6: 6.0031 | L6: =K6/K$16*100 -> 111.16852 | M6: 6.1556 | N6: =M6/M$16*100 -> 115.25183 | S6: 45906.917 | T6: 1.2459 | U6: =T6/T$12*100 -> 88.739316 | V6: 1.3608 | W6: =V6/V$12*100 -> 93.333333 | Y6: Toluene | Z6: =E41/E42 -> 1.416325 | AA6: =E44/E41 -> 0.035956135 | AB6: =M16/M15 -> 43.524615 | AC6: =M10/M16 -> 0 | AD6: =V13/V12 -> 0.95464106 | AE6: =V11/V13 -> 0.017305417
A7: 45902 | B7: 2.1283 | C7: =_xlfn.NORM.DIST(B7,$B$41,$B$44,FALSE) -> 4.0562105 | D7: =B7/$B$42*100 -> 140.98437 | E7: 2.0515 | F7: =_xlfn.NORM.DIST(E7,$E$41,$E$44,FALSE) -> 2.5863103 | G7: =E7/$E$42*100 -> 135.63098 | J7: 45913.875 | K7: 6.637 | L7: =K7/K$16*100 -> 122.90741 | M7: 6.424 | N7: =M7/M$16*100 -> 120.2771
A8: 45903.083 | B8: 2.0188 | C8: =_xlfn.NORM.DIST(B8,$B$41,$B$44,FALSE) -> 2.6016279 | D8: =B8/$B$42*100 -> 133.73079 | E8: 2.0539 | F8: =_xlfn.NORM.DIST(E8,$E$41,$E$44,FALSE) -> 2.6817393 | G8: =E8/$E$42*100 -> 135.78965 | J8: 45920.875 | K8: 6.379 | L8: =K8/K$16*100 -> 118.12963 | M8: 6.4225 | N8: =M8/M$16*100 -> 120.24902 | S8: 45920.917 | T8: 1.2813 | U8: =T8/T$12*100 -> 91.260684 | V8: 1.4195 | W8: =V8/V$12*100 -> 97.359396
A9: 45904 | B9: 2.091 | C9: =_xlfn.NORM.DIST(B9,$B$41,$B$44,FALSE) -> 4.0242601 | D9: =B9/$B$42*100 -> 138.51351 | E9: 2.1645 | F9: =_xlfn.NORM.DIST(E9,$E$41,$E$44,FALSE) -> 4.9680543 | G9: =E9/$E$42*100 -> 143.10176 | J9: 45927.875 | K9: 6.3006 | L9: =K9/K$16*100 -> 116.67778 | M9: 6.463 | N9: =M9/M$16*100 -> 121.0073 | S9: 45927.917 | T9: 1.2836 | U9: =T9/T$12*100 -> 91.424501 | V9: 1.3953 | W9: =V9/V$12*100 -> 95.699588
A10: 45905.083 | B10: 2.1541 | C10: =_xlfn.NORM.DIST(B10,$B$41,$B$44,FALSE) -> 3.7398605 | D10: =B10/$B$42*100 -> 142.69343 | E10: 2.1149 | F10: =_xlfn.NORM.DIST(E10,$E$41,$E$44,FALSE) -> 4.8621954 | G10: =E10/$E$42*100 -> 139.82255
A11: 45906 | B11: 1.9671 | C11: =_xlfn.NORM.DIST(B11,$B$41,$B$44,FALSE) -> 1.3535922 | D11: =B11/$B$42*100 -> 130.30604 | E11: 2.0402 | F11: =_xlfn.NORM.DIST(E11,$E$41,$E$44,FALSE) -> 2.1524094 | G11: =E11/$E$42*100 -> 134.88391 | S11: Std Dev | T11: =_xlfn.STDEV.P(T6:T10) -> 0.017255402 | U11: =_xlfn.STDEV.P(U6:U10) -> 1.2290172 | V11: =_xlfn.STDEV.P(V6:V9) -> 0.024086834 | W11: =_xlfn.STDEV.P(W6:W9) -> 1.6520462
A12: 45907.083 | B12: 2.1497 | C12: =_xlfn.NORM.DIST(B12,$B$41,$B$44,FALSE) -> 3.8110679 | D12: =B12/$B$42*100 -> 142.40196 | E12: 2.0813 | F12: =_xlfn.NORM.DIST(E12,$E$41,$E$44,FALSE) -> 3.7860422 | G12: =E12/$E$42*100 -> 137.60115 | S12: Target | T12: =$U$2*T2 -> 1.404 | V12: =$V$2*$T$2 -> 1.458
A13: 45907.125 | B13: 2.0226 | C13: =_xlfn.NORM.DIST(B13,$B$41,$B$44,FALSE) -> 2.6991399 | D13: =B13/$B$42*100 -> 133.98251 | E13: 2.1304 | F13: =_xlfn.NORM.DIST(E13,$E$41,$E$44,FALSE) -> 5.1179893 | G13: =E13/$E$42*100 -> 140.84731 | S13: Average | T13: =AVERAGE(T6:T10) -> 1.2702667 | U13: =AVERAGE(U6:U10) -> 90.474834 | V13: =AVERAGE(V6:V9) -> 1.3918667 | W13: =AVERAGE(W6:W9) -> 95.464106
A14: 45908 | B14: 1.9328 | C14: =_xlfn.NORM.DIST(B14,$B$41,$B$44,FALSE) -> 0.74994342 | D14: =B14/$B$42*100 -> 128.03392 | E14: 2.0256 | F14: =_xlfn.NORM.DIST(E14,$E$41,$E$44,FALSE) -> 1.6445174 | G14: =E14/$E$42*100 -> 133.91865
A15: 45909.083 | B15: 1.9188 | C15: =_xlfn.NORM.DIST(B15,$B$41,$B$44,FALSE) -> 0.56848202 | D15: =B15/$B$42*100 -> 127.10652 | E15: 1.9698 | F15: =_xlfn.NORM.DIST(E15,$E$41,$E$44,FALSE) -> 0.42222075 | G15: =E15/$E$42*100 -> 130.22954 | J15: Std Dev | K15: =_xlfn.STDEV.P(K6:K14) -> 0.2260409 | L15: =_xlfn.STDEV.P(L6:L14) -> 4.1859425 | M15: =_xlfn.STDEV.P(M6:M14) -> 0.12271217 | N15: =_xlfn.STDEV.P(N6:N14) -> 2.2975505
A16: 45910 | B16: 1.8739 | C16: =_xlfn.NORM.DIST(B16,$B$41,$B$44,FALSE) -> 0.20310166 | D16: =B16/$B$42*100 -> 124.13222 | E16: 1.9276 | F16: =_xlfn.NORM.DIST(E16,$E$41,$E$44,FALSE) -> 0.10656311 | G16: =E16/$E$42*100 -> 127.43957 | J16: Target | K16: =K2*L2*1000*3 -> 5.4 | M16: =K2*M2*1000*7 -> 5.341
A17: 45911 | B17: 2.1568 | C17: =_xlfn.NORM.DIST(B17,$B$41,$B$44,FALSE) -> 3.6930544 | D17: =B17/$B$42*100 -> 142.87228 | E17: 2.1984 | F17: =_xlfn.NORM.DIST(E17,$E$41,$E$44,FALSE) -> 3.9717631 | G17: =E17/$E$42*100 -> 145.34299
A18: 45912.125 | B18: 2.1067 | C18: =_xlfn.NORM.DIST(B18,$B$41,$B$44,FALSE) -> 4.1112365 | D18: =B18/$B$42*100 -> 139.55352 | E18: 2.1807 | F18: =_xlfn.NORM.DIST(E18,$E$41,$E$44,FALSE) -> 4.5732975 | G18: =E18/$E$42*100 -> 144.17279 | J18: Average | K18: =AVERAGE(K6:K14) -> 6.329925 | L18: =AVERAGE(L6:L14) -> 117.22083 | M18: =AVERAGE(M6:M14) -> 6.366275 | N18: =AVERAGE(N6:N14) -> 119.19631
A19: 45913.042 | B19: 2.1754 | C19: =_xlfn.NORM.DIST(B19,$B$41,$B$44,FALSE) -> 3.3154726 | D19: =B19/$B$42*100 -> 144.1044 | E19: 2.1628 | F19: =_xlfn.NORM.DIST(E19,$E$41,$E$44,FALSE) -> 4.9985715 | G19: =E19/$E$42*100 -> 142.98937
A20: 45913.417 | B20: 2.1224 | C20: =_xlfn.NORM.DIST(B20,$B$41,$B$44,FALSE) -> 4.0912936 | D20: =B20/$B$42*100 -> 140.59353 | E20: 2.1974 | F20: =_xlfn.NORM.DIST(E20,$E$41,$E$44,FALSE) -> 4.0091726 | G20: =E20/$E$42*100 -> 145.27688
A21: 45914.542 | B21: 2.343 | C21: =_xlfn.NORM.DIST(B21,$B$41,$B$44,FALSE) -> 0.23819745 | D21: =B21/$B$42*100 -> 155.20668 | E21: 2.2249 | F21: =_xlfn.NORM.DIST(E21,$E$41,$E$44,FALSE) -> 2.913533 | G21: =E21/$E$42*100 -> 147.09499
A22: 45914.583 | B22: 2.2293 | C22: =_xlfn.NORM.DIST(B22,$B$41,$B$44,FALSE) -> 1.9699627 | D22: =B22/$B$42*100 -> 147.67488 | E22: 2.2461 | F22: =_xlfn.NORM.DIST(E22,$E$41,$E$44,FALSE) -> 2.0881412 | G22: =E22/$E$42*100 -> 148.49659
A23: 45915 | B23: 2.1932 | C23: =_xlfn.NORM.DIST(B23,$B$41,$B$44,FALSE) -> 2.8889445 | D23: =B23/$B$42*100 -> 145.28352 | E23: 2.183 | F23: =_xlfn.NORM.DIST(E23,$E$41,$E$44,FALSE) -> 4.5036768 | G23: =E23/$E$42*100 -> 144.32485
A24: 45916.083 | B24: 2.2566 | C24: =_xlfn.NORM.DIST(B24,$B$41,$B$44,FALSE) -> 1.3449072 | D24: =B24/$B$42*100 -> 149.48331 | E24: 2.204 | F24: =_xlfn.NORM.DIST(E24,$E$41,$E$44,FALSE) -> 3.7569094 | G24: =E24/$E$42*100 -> 145.71323 | H24: 0 | I24: =$E$42 -> 1.51256
A25: 45917 | B25: 2.1553 | C25: =_xlfn.NORM.DIST(B25,$B$41,$B$44,FALSE) -> 3.7193414 | D25: =B25/$B$42*100 -> 142.77292 | E25: 2.2609 | F25: =_xlfn.NORM.DIST(E25,$E$41,$E$44,FALSE) -> 1.5822363 | G25: =E25/$E$42*100 -> 149.47506 | H25: 1 | I25: =$E$42 -> 1.51256
A26: 45918.083 | B26: 2.1735 | C26: =_xlfn.NORM.DIST(B26,$B$41,$B$44,FALSE) -> 3.3578696 | D26: =B26/$B$42*100 -> 143.97854 | E26: 2.2693 | F26: =_xlfn.NORM.DIST(E26,$E$41,$E$44,FALSE) -> 1.3297003 | G26: =E26/$E$42*100 -> 150.03041 | H26: 2 | I26: =$E$42 -> 1.51256
A27: 45919 | B27: 2.2039 | C27: =_xlfn.NORM.DIST(B27,$B$41,$B$44,FALSE) -> 2.6166009 | D27: =B27/$B$42*100 -> 145.99232 | E27: 2.1519 | F27: =_xlfn.NORM.DIST(E27,$E$41,$E$44,FALSE) -> 5.1389231 | G27: =E27/$E$42*100 -> 142.26874 | H27: 3 | I27: =$E$42 -> 1.51256
A28: 45920.083 | B28: 2.0459 | C28: =_xlfn.NORM.DIST(B28,$B$41,$B$44,FALSE) -> 3.2704681 | D28: =B28/$B$42*100 -> 135.52597 | E28: 2.114 | F28: =_xlfn.NORM.DIST(E28,$E$41,$E$44,FALSE) -> 4.8417158 | G28: =E28/$E$42*100 -> 139.76305 | H28: 4 | I28: =$E$42 -> 1.51256
A29: 45921 | B29: 2.1267 | C29: =_xlfn.NORM.DIST(B29,$B$41,$B$44,FALSE) -> 4.0671842 | D29: =B29/$B$42*100 -> 140.87838 | E29: 2.1467 | F29: =_xlfn.NORM.DIST(E29,$E$41,$E$44,FALSE) -> 5.1706532 | G29: =E29/$E$42*100 -> 141.92495 | H29: 5 | I29: =$E$42 -> 1.51256
A30: 45921.042 | B30: 2.1321 | C30: =_xlfn.NORM.DIST(B30,$B$41,$B$44,FALSE) -> 4.0258661 | D30: =B30/$B$42*100 -> 141.23609 | E30: 2.1533 | F30: =_xlfn.NORM.DIST(E30,$E$41,$E$44,FALSE) -> 5.1264204 | G30: =E30/$E$42*100 -> 142.36129 | H30: 6 | I30: =$E$42 -> 1.51256
A31: 45922.083 | B31: 2.1191 | C31: =_xlfn.NORM.DIST(B31,$B$41,$B$44,FALSE) -> 4.1044091 | D31: =B31/$B$42*100 -> 140.37493 | E31: 2.1598 | F31: =_xlfn.NORM.DIST(E31,$E$41,$E$44,FALSE) -> 5.0468831 | G31: =E31/$E$42*100 -> 142.79103 | H31: 7 | I31: =$E$42 -> 1.51256
A32: 45923 | B32: 2.1813 | C32: =_xlfn.NORM.DIST(B32,$B$41,$B$44,FALSE) -> 3.1794013 | D32: =B32/$B$42*100 -> 144.49523 | E32: 2.1712 | F32: =_xlfn.NORM.DIST(E32,$E$41,$E$44,FALSE) -> 4.8266381 | G32: =E32/$E$42*100 -> 143.54472 | H32: 8 | I32: =$E$42 -> 1.51256
A33: 45924.083 | B33: 2.1973 | C33: =_xlfn.NORM.DIST(B33,$B$41,$B$44,FALSE) -> 2.7854 | D33: =B33/$B$42*100 -> 145.55511 | E33: 2.163 | F33: =_xlfn.NORM.DIST(E33,$E$41,$E$44,FALSE) -> 4.9950978 | G33: =E33/$E$42*100 -> 143.00259 | H33: 9 | I33: =$E$42 -> 1.51256
A34: 45925 | B34: 2.0223 | C34: =_xlfn.NORM.DIST(B34,$B$41,$B$44,FALSE) -> 2.6914609 | D34: =B34/$B$42*100 -> 133.96264 | E34: 2.1953 | F34: =_xlfn.NORM.DIST(E34,$E$41,$E$44,FALSE) -> 4.0866409 | G34: =E34/$E$42*100 -> 145.13804 | H34: 10 | I34: =$E$42 -> 1.51256
A35: 45926.083 | B35: 2.1021 | C35: =_xlfn.NORM.DIST(B35,$B$41,$B$44,FALSE) -> 4.0966811 | D35: =B35/$B$42*100 -> 139.24881 | E35: 2.1075 | F35: =_xlfn.NORM.DIST(E35,$E$41,$E$44,FALSE) -> 4.6773495 | G35: =E35/$E$42*100 -> 139.33332 | H35: 11 | I35: =$E$42 -> 1.51256
... A40: 45930.083 | B40: 2.1511 | C40: =_xlfn.NORM.DIST(B40,$B$41,$B$44,FALSE) -> 3.7891123 | D40: =B40/$B$42*100 -> 142.4947 | E40: 2.1837 | F40: =_xlfn.NORM.DIST(E40,$E$41,$E$44,FALSE) -> 4.4819058 | G40: =E40/$E$42*100 -> 144.37113 | H40: 16 | I40: =$E$42 -> 1.51256
A41: Average | B41: =AVERAGE(B6:B39) -> 2.1116412 | E41: =AVERAGE(E6:E39) -> 2.1422765 | H41: 17 | I41: =$E$42 -> 1.51256
A42: Target 1 | B42: =B2*C2*1000*3 -> 1.5096 | E42: =B2*D2*1000*7 -> 1.51256 | H42: 18 | I42: =$E$42 -> 1.51256
A43: Target 2 | B43: =B3*C3*1000*3 -> 0 | E43: =B3*D3*1000*7 -> 0 | H43: 19 | I43: =$E$42 -> 1.51256
A44: Std Dev | B44: =_xlfn.STDEV.P(B6:B39) -> 0.096911006 | E44: =_xlfn.STDEV.P(E6:E39) -> 0.077027982 | H44: 20 | I44: =$E$42 -> 1.51256
...
