Workbook

Sheet Validator Notes
A4: Site
A5: Month/Year
A6: Validator | B6: Aengstrom
A8: Validation Prep: | E8: Notes:
B9: Verify all Daily-ZIP folders are downloaded into U:\PLAN\AMC\GC-Agilent+Markes\Data\ORIGINAL\{YYYY}\{YYYYMM}
B10: Verify Operator Reprocessed zip folders are downloaded into U:\PLAN\AMC\GC-Agilent+Markes\Data\ORIGINAL\{YYYY}\{YYYYMM}
B11: Verify all data has been extracted to C:\Users\{Username}\Documents\AutoGC Data\{SiteID}\{YYYY}\{YYYYMM}
B12: Set up folder for validation with four folders in it (AQS, Final, MDVR, Original) name for the folder follows the format of two digit site ID, YYYYMM, version# (HW202604v1)
B13: Transfer all documented communications with operator(s) to MDVR folder.
B14: Ensure dates, times, and site names/numbers in files match up and are continuous. document any missing files on the Validation Notes.
B15: Verify all Original TX1 files loaded into MAX
B16: Check CVS, Blanks, and LCS Reports and noting failures
B17: Download Crosstab into MDVR folder pre changes
A19: Review Oplog:
B20: View and Print the Operator Log Book (Desktop), Op Log backup (D:\EZ\HW-meth), and Operator Checklist (Desktop) from the HW-GC computer with 72 hours on either side of the month. Review and highlight major events in the operator log book such as optimizations, cylinder changes, major events (calibrations), major malfunctions (power failures, trap, oven door failures), etc. Highlight hours for review during or around major events as necessary per operator log book.
B21: Note Stock Cylinder Changes, Verify in MAX, and document in Reference Info Tab
B22: Were EPA PT samples included in this month?
B23: Was an MDL performed? (Include Spreadsheet from Operations)
B24: Was Annual PM performed this month?
B25: Was there a new calibration Curve - Calculated RPD? (Include Spreadsheet in MDVR)
A27: Review Quicklooks:
B28: Dates (1-31) Hours (A-X)
B29: Invalidate missing hours
B30: Samples over calibration range - make sure it is flagged as over the calibration range.
B31: Invalidate data collection errors
B32: Pick hours to view (1st/last month, surrounding invalidations, etc.)
B33: Highlight at least 3 hours to review daily on each column’s hourly grid page. Ideally one hour will be reviewed for each of the following time span; Morning Commute (05-10), Afternoon (11-18); Night (0-4, or 19-23). Try not to exceed 10 hours between checked hours.
A35: Review Chromatography:
B36: All QC samples have been viewed
B37: All highlighted hours have been viewed
B38: If reprocessed, view reprocessed QC
B39: View hours before & after validation method modifications (including peak shifting)
B40: View hours before & after invalidations
B41: Invalidate TMNHC/TC if invalidating 8+ compounds
B42: If invalidating more than 75% of analytes in a column, invalidate all analytes in the column.
B43: If invalidating >336 hour or 14-days, of data loss; Generate memo of data loss.
B44: Send necessary emails and save a copy in the MDVR folder for general issues, 336-hr data losses, and ambient over-ranges.
A47: Validator Notes
A49: Site
A50: Month/Year
...

Sheet QC Review
A1: QC (CVS, CVS Precision, LCS, RTS, BLANK, Audit) Review
A3: Site | B3: ='Validator Notes'!B4 -> 0 | D3: Validator | E3: ='Validator Notes'!B6 -> Aengstrom
A4: Month/Year | B4: ='Validator Notes'!B5 -> 0
A6: QC Type | B6: Date/Time | D6: Filename | E6: Plot Column Notes | F6: BP Notes | G6: Actions
A7: RTS
A15: LCS
A22: CVS
A62: CVS Precision
A72: Audit
A73: Blank
A111: Exp. Or Test Sample
AD158: Qulaifier Flag, MD, was applied to all paramaters and hours that measured below the MDL; Qulaifier Flag, ND, was applied to all paramaters and hours that where not detected; Qulaifier Flag, EH, was applied to Isoprene, 2-METHYL-1-PENTENE, 1-Hexene, and n-Dodecane - due to questions about the accuracy of the measurments at the end of the column; Qualif Flag, QX, was applied to ACETYLENE for whole month due to low CVS recovery; Qualif Flag, QX, was applied to BETA-PINENE from 5-1 to 5-16 due to high blank value;

Sheet Reprocessed Data
A3: Site | B3: ='Validator Notes'!B4 -> 0
A4: Month/Year | B4: ='Validator Notes'!B5 -> 0
A5: Validator | B5: ='Validator Notes'!B6 -> Aengstrom
C7: Batch | E7: single file rpo | F7: Data Range | L7: Date
A8: Column | B8: Corrections Made | C8: Sequence | D8: method | E8: data file | F8: Date | G8: Hour | H8: - | I8: Date | J8: Hour | L8: RPO
C31: Batch | E31: single file rpo | F31: Data Range | L31: Date
A32: Column | B32: Corrections Made | C32: Sequence | D32: method | E32: data file | F32: Date | G32: Hour | H32: - | I32: Date | J32: Hour | L32: RPO
C60: Batch | E60: single file rpo | F60: Data Range | L60: Date
A61: Column | B61: Corrections Made | C61: Sequence | D61: method | E61: data file | F61: Date | G61: Hour | H61: - | I61: Date | J61: Hour | L61: RPO
AC89: Qulaifier Flag, MD, was applied to all paramaters and hours that measured below the MDL; Qulaifier Flag, ND, was applied to all paramaters and hours that where not detected; Qulaifier Flag, EH, was applied to Isoprene, 2-METHYL-1-PENTENE, 1-Hexene, and n-Dodecane - due to questions about the accuracy of the measurments at the end of the column; Qualif Flag, QX, was applied to ACETYLENE for whole month due to low CVS recovery; Qualif Flag, QX, was applied to BETA-PINENE from 5-1 to 5-16 due to high blank value;

Sheet Reprocess Plan
C2: Reprocess Plan | N2: Site: | P2: ='Validator Notes'!B4 -> 0 | V2: Month/Year: | Z2: ='Validator Notes'!B5 -> 0 | AZ2: Pg. | BA2: 1
E4: 1 | AD4: 2 | BD4: CVS
E5: 0 | F5: 1 | G5: 2 | H5: 3 | I5: 4 | J5: 5 | K5: 6 | L5: 7 | M5: 8 | N5: 9 | O5: 10 | P5: 11 | Q5: 12 | R5: 13 | S5: 14 | T5: 15 | U5: 16 | V5: 17 | W5: 18 | X5: 19 | Y5: 20 | Z5: 21 | AA5: 22 | AB5: 23 | AD5: 0 | AE5: 1 | AF5: 2 | AG5: 3 | AH5: 4 | AI5: 5 | AJ5: 6 | AK5: 7 | AL5: 8 | AM5: 9 | AN5: 10 | AO5: 11 | AP5: 12 | AQ5: 13 | AR5: 14 | AS5: 15 | AT5: 16 | AU5: 17 | AV5: 18 | AW5: 19 | AX5: 20 | AY5: 21 | AZ5: 22 | BA5: 23 | BD5: Blank
E6: A | F6: B | G6: C | H6: D | I6: E | J6: F | K6: G | L6: H | M6: I | N6: J | O6: K | P6: L | Q6: M | R6: N | S6: O | T6: P | U6: Q | V6: R | W6: S | X6: T | Y6: U | Z6: V | AA6: W | AB6: X | AD6: A | AE6: B | AF6: C | AG6: D | AH6: E | AI6: F | AJ6: G | AK6: H | AL6: I | AM6: J | AN6: K | AO6: L | AP6: M | AQ6: N | AR6: O | AS6: P | AT6: Q | AU6: R | AV6: S | AW6: T | AX6: U | AY6: V | AZ6: W | BA6: X | BD6: LCS
C7: Checked PLOT | BD7: RTS
C8: RPO PLOT | BD8: Experimental/ Test
C9: Checked BP | BD9: Missing Data
C10: RPO BP | BD10: Invalidate
C11: Invalid PLOT | BD11: Check this Hour
C12: Invalid BP | BC12: RP | BD12: Reprocessed file
C13: Op Log | BC13: OK | BD13: Hour reviewed and correct
C14: Notes: | BD14: Multipoint
E15: 3 | AD15: 4 | BD15: Detection Limit
E16: 0 | F16: 1 | G16: 2 | H16: 3 | I16: 4 | J16: 5 | K16: 6 | L16: 7 | M16: 8 | N16: 9 | O16: 10 | P16: 11 | Q16: 12 | R16: 13 | S16: 14 | T16: 15 | U16: 16 | V16: 17 | W16: 18 | X16: 19 | Y16: 20 | Z16: 21 | AA16: 22 | AB16: 23 | AD16: 0 | AE16: 1 | AF16: 2 | AG16: 3 | AH16: 4 | AI16: 5 | AJ16: 6 | AK16: 7 | AL16: 8 | AM16: 9 | AN16: 10 | AO16: 11 | AP16: 12 | AQ16: 13 | AR16: 14 | AS16: 15 | AT16: 16 | AU16: 17 | AV16: 18 | AW16: 19 | AX16: 20 | AY16: 21 | AZ16: 22 | BA16: 23 | BC16: SB | BD16: See Below
E17: A | F17: B | G17: C | H17: D | I17: E | J17: F | K17: G | L17: H | M17: I | N17: J | O17: K | P17: L | Q17: M | R17: N | S17: O | T17: P | U17: Q | V17: R | W17: S | X17: T | Y17: U | Z17: V | AA17: W | AB17: X | AD17: A | AE17: B | AF17: C | AG17: D | AH17: E | AI17: F | AJ17: G | AK17: H | AL17: I | AM17: J | AN17: K | AO17: L | AP17: M | AQ17: N | AR17: O | AS17: P | AT17: Q | AU17: R | AV17: S | AW17: T | AX17: U | AY17: V | AZ17: W | BA17: X
C18: Checked PLOT
C19: RPO PLOT
C20: Checked BP
C21: RPO BP
C22: Invalid PLOT
C23: Invalid BP
C24: Op Log
C25: Notes:
E26: 5 | AD26: 6
E27: 0 | F27: 1 | G27: 2 | H27: 3 | I27: 4 | J27: 5 | K27: 6 | L27: 7 | M27: 8 | N27: 9 | O27: 10 | P27: 11 | Q27: 12 | R27: 13 | S27: 14 | T27: 15 | U27: 16 | V27: 17 | W27: 18 | X27: 19 | Y27: 20 | Z27: 21 | AA27: 22 | AB27: 23 | AD27: 0 | AE27: 1 | AF27: 2 | AG27: 3 | AH27: 4 | AI27: 5 | AJ27: 6 | AK27: 7 | AL27: 8 | AM27: 9 | AN27: 10 | AO27: 11 | AP27: 12 | AQ27: 13 | AR27: 14 | AS27: 15 | AT27: 16 | AU27: 17 | AV27: 18 | AW27: 19 | AX27: 20 | AY27: 21 | AZ27: 22 | BA27: 23
E28: A | F28: B | G28: C | H28: D | I28: E | J28: F | K28: G | L28: H | M28: I | N28: J | O28: K | P28: L | Q28: M | R28: N | S28: O | T28: P | U28: Q | V28: R | W28: S | X28: T | Y28: U | Z28: V | AA28: W | AB28: X | AD28: A | AE28: B | AF28: C | AG28: D | AH28: E | AI28: F | AJ28: G | AK28: H | AL28: I | AM28: J | AN28: K | AO28: L | AP28: M | AQ28: N | AR28: O | AS28: P | AT28: Q | AU28: R | AV28: S | AW28: T | AX28: U | AY28: V | AZ28: W | BA28: X
C29: Checked PLOT
C30: RPO PLOT
C31: Checked BP
C32: RPO BP
C33: Invalid PLOT
C34: Invalid BP
C35: Op Log
C36: Notes:
E37: 7 | AD37: 8
E38: 0 | F38: 1 | G38: 2 | H38: 3 | I38: 4 | J38: 5 | K38: 6 | L38: 7 | M38: 8 | N38: 9 | O38: 10 | P38: 11 | Q38: 12 | R38: 13 | S38: 14 | T38: 15 | U38: 16 | V38: 17 | W38: 18 | X38: 19 | Y38: 20 | Z38: 21 | AA38: 22 | AB38: 23 | AD38: 0 | AE38: 1 | AF38: 2 | AG38: 3 | AH38: 4 | AI38: 5 | AJ38: 6 | AK38: 7 | AL38: 8 | AM38: 9 | AN38: 10 | AO38: 11 | AP38: 12 | AQ38: 13 | AR38: 14 | AS38: 15 | AT38: 16 | AU38: 17 | AV38: 18 | AW38: 19 | AX38: 20 | AY38: 21 | AZ38: 22 | BA38: 23
E39: A | F39: B | G39: C | H39: D | I39: E | J39: F | K39: G | L39: H | M39: I | N39: J | O39: K | P39: L | Q39: M | R39: N | S39: O | T39: P | U39: Q | V39: R | W39: S | X39: T | Y39: U | Z39: V | AA39: W | AB39: X | AD39: A | AE39: B | AF39: C | AG39: D | AH39: E | AI39: F | AJ39: G | AK39: H | AL39: I | AM39: J | AN39: K | AO39: L | AP39: M | AQ39: N | AR39: O | AS39: P | AT39: Q | AU39: R | AV39: S | AW39: T | AX39: U | AY39: V | AZ39: W | BA39: X
C40: Checked PLOT
C41: RPO PLOT
C42: Checked BP
...

Sheet QUALIFIERS_NULL 
A1: QUALIFIERS / NULL
A3: Site | B3: ='Validator Notes'!B4 -> 0
A4: Month/Year | B4: ='Validator Notes'!B5 -> 0
A5: Validator | B5: ='Validator Notes'!B6 -> Aengstrom
A7: Null | R7: Common Null Flags | U7: Null
J8: DATE/TIME RANGE | R8: Code | S8: Description | AD8: DATE/TIME RANGE
A9: Paramater (s) | D9: COMPOUND(S) or WHOLE HOUR(S) - REASON | I9: CODE | J9: Date | K9: Hour | L9: - | M9: Date | N9: Hour | O9: Justification | P9: Hours | R9: AF | S9: Scheduled but not Collected (Lost) | U9: Paramater (s) | X9: COMPOUND(S) or WHOLE HOUR(S) - REASON | AC9: CODE | AD9: Date | AE9: Hour | AF9: - | AG9: Date | AH9: Hour | AI9: Justification
K10: 0 | L10: - | N10: 23 | P10: =IF(ISBLANK(J10),,((M10+N10)-(J10+K10))*24+1) -> 0 | R10: AG | S10: Sample Time Out of Limits | AE10: 0 | AF10: - | AH10: 23
K11: 0 | L11: - | N11: 23 | P11: =IF(ISBLANK(J11),,((M11+N11)-(J11+K11))*24+1) -> 0 | R11: AH | S11: Sample Flow Rate out of Limits | AE11: 0 | AF11: - | AH11: 23
K12: 0 | L12: - | N12: 23 | P12: =IF(ISBLANK(J12),,((M12+N12)-(J12+K12))*24+1) -> 0 | R12: AI | S12: Insufficient Data (Invalid Sample Time) | AE12: 0 | AF12: - | AH12: 23
K13: 0 | L13: - | N13: 23 | P13: =IF(ISBLANK(J13),,((M13+N13)-(J13+K13))*24+1) -> 0 | R13: AM | S13: Misc. Void | AE13: 0 | AF13: - | AH13: 23
K14: 0 | L14: - | N14: 23 | P14: =IF(ISBLANK(J14),,((M14+N14)-(J14+K14))*24+1) -> 0 | R14: AN | S14: Machine Malfunction | AE14: 0 | AF14: - | AH14: 23
K15: 0 | L15: - | N15: 23 | P15: =IF(ISBLANK(J15),,((M15+N15)-(J15+K15))*24+1) -> 0 | R15: AQ | S15: Collection Error | AE15: 0 | AF15: - | AH15: 23
K16: 0 | L16: - | N16: 23 | P16: =IF(ISBLANK(J16),,((M16+N16)-(J16+K16))*24+1) -> 0 | R16: AS | S16: Poor QA results | AE16: 0 | AF16: - | AH16: 23
K17: 0 | L17: - | N17: 23 | P17: =IF(ISBLANK(J17),,((M17+N17)-(J17+K17))*24+1) -> 0 | R17: AT | S17: Calibration | AE17: 0 | AF17: - | AH17: 23
K18: 0 | L18: - | N18: 23 | P18: =IF(ISBLANK(J18),,((M18+N18)-(J18+K18))*24+1) -> 0 | R18: AV | S18: Power Failure | AE18: 0 | AF18: - | AH18: 23
K19: 0 | L19: - | N19: 23 | P19: =IF(ISBLANK(J19),,((M19+N19)-(J19+K19))*24+1) -> 0 | R19: AX | S19: Precision Check | AE19: 0 | AF19: - | AH19: 23
K20: 0 | L20: - | N20: 23 | P20: =IF(ISBLANK(J20),,((M20+N20)-(J20+K20))*24+1) -> 0 | R20: AY | S20: QC Control Points, Zero/Span | AE20: 0 | AF20: - | AH20: 23
K21: 0 | L21: - | N21: 23 | P21: =IF(ISBLANK(J21),,((M21+N21)-(J21+K21))*24+1) -> 0 | R21: AZ | S21: QC Audit (Audit Sample) | AE21: 0 | AF21: - | AH21: 23
P22: =IF(ISBLANK(J22),,((M22+N22)-(J22+K22))*24+1) -> 0 | R22: BA | S22: Maintenances / Routine Repairs
P23: =IF(ISBLANK(J23),,((M23+N23)-(J23+K23))*24+1) -> 0 | R23: BH | S23: Interference, Co-elution, Misid
P24: =IF(ISBLANK(J24),,((M24+N24)-(J24+K24))*24+1) -> 0 | R24: BJ | S24: Operator Error
P25: =IF(ISBLANK(J25),,((M25+N25)-(J25+K25))*24+1) -> 0 | R25: BK | S25: Site Computer, Data Logger Down
R26: DA | S26: Aberrant Data, Corrupt Files, Spikes, Shifts
A27: QUALIFIERS | R27: DL | S27: Detection Limit | U27: QUALIFIERS
J28: DATE/TIME RANGE | R28: TC | S28: Component Check & RTS (RTS) | AD28: DATE/TIME RANGE
A29: Paramater (s) | D29: COMPOUND(S) or WHOLE HOUR(S) - REASON | I29: CODE | J29: Date | K29: Hour | L29: - | M29: Date | N29: Hour | O29: Justification | P29: Hours | R29: XX | S29: Experimental Data | U29: Paramater (s) | X29: COMPOUND(S) or WHOLE HOUR(S) - REASON | AC29: CODE | AD29: Date | AE29: Hour | AF29: - | AG29: Date | AH29: Hour | AI29: Justification
K30: 0 | L30: - | N30: 23 | P30: =IF(ISBLANK(J30),,((M30+N30)-(J30+K30))*24+1) -> 0 | AE30: 0 | AF30: - | AH30: 23
K31: 0 | L31: - | N31: 23 | P31: =IF(ISBLANK(J31),,((M31+N31)-(J31+K31))*24+1) -> 0 | AE31: 0 | AF31: - | AH31: 23
K32: 0 | L32: - | N32: 23 | P32: =IF(ISBLANK(J32),,((M32+N32)-(J32+K32))*24+1) -> 0 | AE32: 0 | AF32: - | AH32: 23
K33: 0 | L33: - | N33: 23 | P33: =IF(ISBLANK(J33),,((M33+N33)-(J33+K33))*24+1) -> 0 | AE33: 0 | AF33: - | AH33: 23
K34: 0 | L34: - | N34: 23 | P34: =IF(ISBLANK(J34),,((M34+N34)-(J34+K34))*24+1) -> 0 | R34: Common Qualifier Flag | AE34: 0 | AF34: - | AH34: 23
L35: - | P35: =IF(ISBLANK(J35),,((M35+N35)-(J35+K35))*24+1) -> 0 | R35: Code | S35: Description | AF35: -
L36: - | P36: =IF(ISBLANK(J36),,((M36+N36)-(J36+K36))*24+1) -> 0 | R36: LJ | S36: ID acceptable; Value is Estimate | AF36: -
L37: - | P37: =IF(ISBLANK(J37),,((M37+N37)-(J37+K37))*24+1) -> 0 | R37: LL | S37: ID; Value Biased Low | AF37: -
L38: - | P38: =IF(ISBLANK(J38),,((M38+N38)-(J38+K38))*24+1) -> 0 | R38: LK | S38: ID; Value Biased High | AF38: -
L39: - | P39: =IF(ISBLANK(J39),,((M39+N39)-(J39+K39))*24+1) -> 0 | R39: QX | S39: Does not Meet QC Criteria | AF39: -
L40: - | P40: =IF(ISBLANK(J40),,((M40+N40)-(J40+K40))*24+1) -> 0 | R40: EH | S40: Estimated; Exceeds Upper Range | AF40: -
L41: - | P41: =IF(ISBLANK(J41),,((M41+N41)-(J41+K41))*24+1) -> 0 | R41: ND | S41: No Value Detected; Non Detect | AF41: -
L42: - | P42: =IF(ISBLANK(J42),,((M42+N42)-(J42+K42))*24+1) -> 0 | R42: MD | S42: Value Less Than MDL (<MDL) | AF42: -
...

Sheet Reference Info
B1: Site | C1: ='Validator Notes'!B4 -> 0 | E1: Validator | G1: ='Validator Notes'!B6 -> Aengstrom
B2: Month/Year | C2: ='Validator Notes'!B5 -> 0
B3: *See Validation SOP for calculations.
A4: Standards and References: | E4: PLOT | I4: BP | M4: Calibrant Target
A5: Standard | B5: Canister Lot# | C5: Blend Ratio | D5: Start Date | E5: Std Dev (ppbC) | F5: Average (ppbC) | G5: % Bias | H5: % Error | I5: Std Ave (ppbC) | J5: Average (ppbC) | K5: % Bias | L5: % Error | M5: PLOT (ppbC) | N5: BP (ppbC) | O5: Notes:
A6: CVS
A7: LCS
A8: RTS
B13: RF | D13: RSD | G13: EH (Calibration Range)
A14: Calibration | B14: PLOT | C14: BP | D14: PLOT | E14: BP | G14: PLOT (ppbC) | H14: BP (ppbC) | I14: Reference File: | L14: Notes:

Sheet Calculations
A1: CVS Results | H1: LCS Results
B2: Propane | C2: Recovery | D2: Normal Distribution | E2: Toluene | F2: Recovery | G2: Normal Distribution | I2: Propane | J2: Recovery | K2: Toluene | L2: Recovery
A3: DATE/TIME | B3: 43204 | E3: 45202 | H3: DATE/TIME | I3: 43204 | K3: 45202
C4: =B4/'Reference Info'!M$6 -> #DIV/0! | D4: =_xlfn.NORM.DIST(B4,'Reference Info'!F$6,'Reference Info'!E$6,FALSE) -> #NUM! | F4: =E4/'Reference Info'!N$6 -> #DIV/0! | G4: =_xlfn.NORM.DIST(E4,'Reference Info'!J$6,'Reference Info'!I$6,FALSE) -> #NUM!
C5: =B5/'Reference Info'!M$6 -> #DIV/0! | D5: =_xlfn.NORM.DIST(B5,'Reference Info'!F$6,'Reference Info'!E$6,FALSE) -> #NUM! | F5: =E5/'Reference Info'!N$6 -> #DIV/0! | G5: =_xlfn.NORM.DIST(E5,'Reference Info'!J$6,'Reference Info'!I$6,FALSE) -> #NUM!
C6: =B6/'Reference Info'!M$6 -> #DIV/0! | D6: =_xlfn.NORM.DIST(B6,'Reference Info'!F$6,'Reference Info'!E$6,FALSE) -> #NUM! | F6: =E6/'Reference Info'!N$6 -> #DIV/0! | G6: =_xlfn.NORM.DIST(E6,'Reference Info'!J$6,'Reference Info'!I$6,FALSE) -> #NUM!
C7: =B7/'Reference Info'!M$6 -> #DIV/0! | D7: =_xlfn.NORM.DIST(B7,'Reference Info'!F$6,'Reference Info'!E$6,FALSE) -> #NUM! | F7: =E7/'Reference Info'!N$6 -> #DIV/0! | G7: =_xlfn.NORM.DIST(E7,'Reference Info'!J$6,'Reference Info'!I$6,FALSE) -> #NUM!
C8: =B8/'Reference Info'!M$6 -> #DIV/0! | D8: =_xlfn.NORM.DIST(B8,'Reference Info'!F$6,'Reference Info'!E$6,FALSE) -> #NUM! | F8: =E8/'Reference Info'!N$6 -> #DIV/0! | G8: =_xlfn.NORM.DIST(E8,'Reference Info'!J$6,'Reference Info'!I$6,FALSE) -> #NUM!
C9: =B9/'Reference Info'!M$6 -> #DIV/0! | D9: =_xlfn.NORM.DIST(B9,'Reference Info'!F$6,'Reference Info'!E$6,FALSE) -> #NUM! | F9: =E9/'Reference Info'!N$6 -> #DIV/0! | G9: =_xlfn.NORM.DIST(E9,'Reference Info'!J$6,'Reference Info'!I$6,FALSE) -> #NUM!
C10: =B10/'Reference Info'!M$6 -> #DIV/0! | D10: =_xlfn.NORM.DIST(B10,'Reference Info'!F$6,'Reference Info'!E$6,FALSE) -> #NUM! | F10: =E10/'Reference Info'!N$6 -> #DIV/0! | G10: =_xlfn.NORM.DIST(E10,'Reference Info'!J$6,'Reference Info'!I$6,FALSE) -> #NUM!
C11: =B11/'Reference Info'!M$6 -> #DIV/0! | D11: =_xlfn.NORM.DIST(B11,'Reference Info'!F$6,'Reference Info'!E$6,FALSE) -> #NUM! | F11: =E11/'Reference Info'!N$6 -> #DIV/0! | G11: =_xlfn.NORM.DIST(E11,'Reference Info'!J$6,'Reference Info'!I$6,FALSE) -> #NUM!
C12: =B12/'Reference Info'!M$6 -> #DIV/0! | D12: =_xlfn.NORM.DIST(B12,'Reference Info'!F$6,'Reference Info'!E$6,FALSE) -> #NUM! | F12: =E12/'Reference Info'!N$6 -> #DIV/0! | G12: =_xlfn.NORM.DIST(E12,'Reference Info'!J$6,'Reference Info'!I$6,FALSE) -> #NUM!
C13: =B13/'Reference Info'!M$6 -> #DIV/0! | D13: =_xlfn.NORM.DIST(B13,'Reference Info'!F$6,'Reference Info'!E$6,FALSE) -> #NUM! | F13: =E13/'Reference Info'!N$6 -> #DIV/0! | G13: =_xlfn.NORM.DIST(E13,'Reference Info'!J$6,'Reference Info'!I$6,FALSE) -> #NUM!
C14: =B14/'Reference Info'!M$6 -> #DIV/0! | D14: =_xlfn.NORM.DIST(B14,'Reference Info'!F$6,'Reference Info'!E$6,FALSE) -> #NUM! | F14: =E14/'Reference Info'!N$6 -> #DIV/0! | G14: =_xlfn.NORM.DIST(E14,'Reference Info'!J$6,'Reference Info'!I$6,FALSE) -> #NUM!
C15: =B15/'Reference Info'!M$6 -> #DIV/0! | D15: =_xlfn.NORM.DIST(B15,'Reference Info'!F$6,'Reference Info'!E$6,FALSE) -> #NUM! | F15: =E15/'Reference Info'!N$6 -> #DIV/0! | G15: =_xlfn.NORM.DIST(E15,'Reference Info'!J$6,'Reference Info'!I$6,FALSE) -> #NUM!
C16: =B16/'Reference Info'!M$6 -> #DIV/0! | D16: =_xlfn.NORM.DIST(B16,'Reference Info'!F$6,'Reference Info'!E$6,FALSE) -> #NUM! | F16: =E16/'Reference Info'!N$6 -> #DIV/0! | G16: =_xlfn.NORM.DIST(E16,'Reference Info'!J$6,'Reference Info'!I$6,FALSE) -> #NUM! | H16: RTS Results
C17: =B17/'Reference Info'!M$6 -> #DIV/0! | D17: =_xlfn.NORM.DIST(B17,'Reference Info'!F$6,'Reference Info'!E$6,FALSE) -> #NUM! | F17: =E17/'Reference Info'!N$6 -> #DIV/0! | G17: =_xlfn.NORM.DIST(E17,'Reference Info'!J$6,'Reference Info'!I$6,FALSE) -> #NUM! | I17: Propane | J17: Recovery | K17: Toluene | L17: Recovery
C18: =B18/'Reference Info'!M$6 -> #DIV/0! | D18: =_xlfn.NORM.DIST(B18,'Reference Info'!F$6,'Reference Info'!E$6,FALSE) -> #NUM! | F18: =E18/'Reference Info'!N$6 -> #DIV/0! | G18: =_xlfn.NORM.DIST(E18,'Reference Info'!J$6,'Reference Info'!I$6,FALSE) -> #NUM! | H18: DATE/TIME | I18: 43204 | K18: 45202
C19: =B19/'Reference Info'!M$6 -> #DIV/0! | D19: =_xlfn.NORM.DIST(B19,'Reference Info'!F$6,'Reference Info'!E$6,FALSE) -> #NUM! | F19: =E19/'Reference Info'!N$6 -> #DIV/0! | G19: =_xlfn.NORM.DIST(E19,'Reference Info'!J$6,'Reference Info'!I$6,FALSE) -> #NUM! | J19: =I19/'Reference Info'!M$7 -> #DIV/0! | L19: =K19/'Reference Info'!N$7 -> #DIV/0!
C20: =B20/'Reference Info'!M$6 -> #DIV/0! | D20: =_xlfn.NORM.DIST(B20,'Reference Info'!F$6,'Reference Info'!E$6,FALSE) -> #NUM! | F20: =E20/'Reference Info'!N$6 -> #DIV/0! | G20: =_xlfn.NORM.DIST(E20,'Reference Info'!J$6,'Reference Info'!I$6,FALSE) -> #NUM! | J20: =I20/'Reference Info'!M$7 -> #DIV/0! | L20: =K20/'Reference Info'!N$7 -> #DIV/0!
C21: =B21/'Reference Info'!M$6 -> #DIV/0! | D21: =_xlfn.NORM.DIST(B21,'Reference Info'!F$6,'Reference Info'!E$6,FALSE) -> #NUM! | F21: =E21/'Reference Info'!N$6 -> #DIV/0! | G21: =_xlfn.NORM.DIST(E21,'Reference Info'!J$6,'Reference Info'!I$6,FALSE) -> #NUM! | J21: =I21/'Reference Info'!M$7 -> #DIV/0! | L21: =K21/'Reference Info'!N$7 -> #DIV/0!
C22: =B22/'Reference Info'!M$6 -> #DIV/0! | D22: =_xlfn.NORM.DIST(B22,'Reference Info'!F$6,'Reference Info'!E$6,FALSE) -> #NUM! | F22: =E22/'Reference Info'!N$6 -> #DIV/0! | G22: =_xlfn.NORM.DIST(E22,'Reference Info'!J$6,'Reference Info'!I$6,FALSE) -> #NUM! | J22: =I22/'Reference Info'!M$7 -> #DIV/0! | L22: =K22/'Reference Info'!N$7 -> #DIV/0!
C23: =B23/'Reference Info'!M$6 -> #DIV/0! | D23: =_xlfn.NORM.DIST(B23,'Reference Info'!F$6,'Reference Info'!E$6,FALSE) -> #NUM! | F23: =E23/'Reference Info'!N$6 -> #DIV/0! | G23: =_xlfn.NORM.DIST(E23,'Reference Info'!J$6,'Reference Info'!I$6,FALSE) -> #NUM! | J23: =I23/'Reference Info'!M$7 -> #DIV/0! | L23: =K23/'Reference Info'!N$7 -> #DIV/0!
C24: =B24/'Reference Info'!M$6 -> #DIV/0! | D24: =_xlfn.NORM.DIST(B24,'Reference Info'!F$6,'Reference Info'!E$6,FALSE) -> #NUM! | F24: =E24/'Reference Info'!N$6 -> #DIV/0! | G24: =_xlfn.NORM.DIST(E24,'Reference Info'!J$6,'Reference Info'!I$6,FALSE) -> #NUM! | J24: =I24/'Reference Info'!M$7 -> #DIV/0! | L24: =K24/'Reference Info'!N$7 -> #DIV/0!
C25: =B25/'Reference Info'!M$6 -> #DIV/0! | D25: =_xlfn.NORM.DIST(B25,'Reference Info'!F$6,'Reference Info'!E$6,FALSE) -> #NUM! | F25: =E25/'Reference Info'!N$6 -> #DIV/0! | G25: =_xlfn.NORM.DIST(E25,'Reference Info'!J$6,'Reference Info'!I$6,FALSE) -> #NUM! | J25: =I25/'Reference Info'!M$7 -> #DIV/0! | L25: =K25/'Reference Info'!N$7 -> #DIV/0!
C26: =B26/'Reference Info'!M$6 -> #DIV/0! | D26: =_xlfn.NORM.DIST(B26,'Reference Info'!F$6,'Reference Info'!E$6,FALSE) -> #NUM! | F26: =E26/'Reference Info'!N$6 -> #DIV/0! | G26: =_xlfn.NORM.DIST(E26,'Reference Info'!J$6,'Reference Info'!I$6,FALSE) -> #NUM! | J26: =I26/'Reference Info'!M$7 -> #DIV/0! | L26: =K26/'Reference Info'!N$7 -> #DIV/0!
C27: =B27/'Reference Info'!M$6 -> #DIV/0! | D27: =_xlfn.NORM.DIST(B27,'Reference Info'!F$6,'Reference Info'!E$6,FALSE) -> #NUM! | F27: =E27/'Reference Info'!N$6 -> #DIV/0! | G27: =_xlfn.NORM.DIST(E27,'Reference Info'!J$6,'Reference Info'!I$6,FALSE) -> #NUM! | J27: =I27/'Reference Info'!M$7 -> #DIV/0! | L27: =K27/'Reference Info'!N$7 -> #DIV/0!
C28: =B28/'Reference Info'!M$6 -> #DIV/0! | D28: =_xlfn.NORM.DIST(B28,'Reference Info'!F$6,'Reference Info'!E$6,FALSE) -> #NUM! | F28: =E28/'Reference Info'!N$6 -> #DIV/0! | G28: =_xlfn.NORM.DIST(E28,'Reference Info'!J$6,'Reference Info'!I$6,FALSE) -> #NUM! | H28: Target Line
C29: =B29/'Reference Info'!M$6 -> #DIV/0! | D29: =_xlfn.NORM.DIST(B29,'Reference Info'!F$6,'Reference Info'!E$6,FALSE) -> #NUM! | F29: =E29/'Reference Info'!N$6 -> #DIV/0! | G29: =_xlfn.NORM.DIST(E29,'Reference Info'!J$6,'Reference Info'!I$6,FALSE) -> #NUM! | H29: Y Axis | I29: X Axis
C30: =B30/'Reference Info'!M$6 -> #DIV/0! | D30: =_xlfn.NORM.DIST(B30,'Reference Info'!F$6,'Reference Info'!E$6,FALSE) -> #NUM! | F30: =E30/'Reference Info'!N$6 -> #DIV/0! | G30: =_xlfn.NORM.DIST(E30,'Reference Info'!J$6,'Reference Info'!I$6,FALSE) -> #NUM! | H30: 12 | I30: 1
C31: =B31/'Reference Info'!M$6 -> #DIV/0! | D31: =_xlfn.NORM.DIST(B31,'Reference Info'!F$6,'Reference Info'!E$6,FALSE) -> #NUM! | F31: =E31/'Reference Info'!N$6 -> #DIV/0! | G31: =_xlfn.NORM.DIST(E31,'Reference Info'!J$6,'Reference Info'!I$6,FALSE) -> #NUM! | H31: 11 | I31: 1
C32: =B32/'Reference Info'!M$6 -> #DIV/0! | D32: =_xlfn.NORM.DIST(B32,'Reference Info'!F$6,'Reference Info'!E$6,FALSE) -> #NUM! | F32: =E32/'Reference Info'!N$6 -> #DIV/0! | G32: =_xlfn.NORM.DIST(E32,'Reference Info'!J$6,'Reference Info'!I$6,FALSE) -> #NUM! | H32: 10 | I32: 1
C33: =B33/'Reference Info'!M$6 -> #DIV/0! | D33: =_xlfn.NORM.DIST(B33,'Reference Info'!F$6,'Reference Info'!E$6,FALSE) -> #NUM! | F33: =E33/'Reference Info'!N$6 -> #DIV/0! | G33: =_xlfn.NORM.DIST(E33,'Reference Info'!J$6,'Reference Info'!I$6,FALSE) -> #NUM! | H33: 9 | I33: 1
C34: =B34/'Reference Info'!M$6 -> #DIV/0! | D34: =_xlfn.NORM.DIST(B34,'Reference Info'!F$6,'Reference Info'!E$6,FALSE) -> #NUM! | F34: =E34/'Reference Info'!N$6 -> #DIV/0! | G34: =_xlfn.NORM.DIST(E34,'Reference Info'!J$6,'Reference Info'!I$6,FALSE) -> #NUM! | H34: 8 | I34: 1
C35: =B35/'Reference Info'!M$6 -> #DIV/0! | D35: =_xlfn.NORM.DIST(B35,'Reference Info'!F$6,'Reference Info'!E$6,FALSE) -> #NUM! | F35: =E35/'Reference Info'!N$6 -> #DIV/0! | G35: =_xlfn.NORM.DIST(E35,'Reference Info'!J$6,'Reference Info'!I$6,FALSE) -> #NUM! | H35: 7 | I35: 1
C36: =B36/'Reference Info'!M$6 -> #DIV/0! | D36: =_xlfn.NORM.DIST(B36,'Reference Info'!F$6,'Reference Info'!E$6,FALSE) -> #NUM! | F36: =E36/'Reference Info'!N$6 -> #DIV/0! | G36: =_xlfn.NORM.DIST(E36,'Reference Info'!J$6,'Reference Info'!I$6,FALSE) -> #NUM! | H36: 6 | I36: 1
C37: =B37/'Reference Info'!M$6 -> #DIV/0! | D37: =_xlfn.NORM.DIST(B37,'Reference Info'!F$6,'Reference Info'!E$6,FALSE) -> #NUM! | F37: =E37/'Reference Info'!N$6 -> #DIV/0! | G37: =_xlfn.NORM.DIST(E37,'Reference Info'!J$6,'Reference Info'!I$6,FALSE) -> #NUM! | H37: 5 | I37: 1
C38: =B38/'Reference Info'!M$6 -> #DIV/0! | D38: =_xlfn.NORM.DIST(B38,'Reference Info'!F$6,'Reference Info'!E$6,FALSE) -> #NUM! | F38: =E38/'Reference Info'!N$6 -> #DIV/0! | G38: =_xlfn.NORM.DIST(E38,'Reference Info'!J$6,'Reference Info'!I$6,FALSE) -> #NUM! | H38: 4 | I38: 1
C39: =B39/'Reference Info'!M$6 -> #DIV/0! | D39: =_xlfn.NORM.DIST(B39,'Reference Info'!F$6,'Reference Info'!E$6,FALSE) -> #NUM! | F39: =E39/'Reference Info'!N$6 -> #DIV/0! | G39: =_xlfn.NORM.DIST(E39,'Reference Info'!J$6,'Reference Info'!I$6,FALSE) -> #NUM! | H39: 3 | I39: 1
C40: =B40/'Reference Info'!M$6 -> #DIV/0! | D40: =_xlfn.NORM.DIST(B40,'Reference Info'!F$6,'Reference Info'!E$6,FALSE) -> #NUM! | F40: =E40/'Reference Info'!N$6 -> #DIV/0! | G40: =_xlfn.NORM.DIST(E40,'Reference Info'!J$6,'Reference Info'!I$6,FALSE) -> #NUM! | H40: 2 | I40: 1
...
